KNOWNBUG
main.py
--force-malloc-success --unwind 9
^VERIFICATION FAILED$
