CORE
main.py

^Throwing an exception of type ValueError but there is not catch for it.$
