CORE
main.py

^\s*Throwing an exception of type ValueError but there is not catch for it.$
